<robot name="test_robot">
<!--
  <link name="odom">
    <visual>
      <geometry>
        <box size="0.1 0.1 0.1"/>
      </geometry>
      <origin rpy="0 0 0" xyz="0 0 0"/>
      <material name="white">
        <color rgba="0 0 0 1"/>
      </material>
    </visual>
  </link>
-->
  <link name="base_link">
    <visual>
      <geometry>
        <box size="0.16 0.16 0.06"/>
      </geometry>
      <origin rpy="0 0 0" xyz="0 0 0.046"/>
      <material name="green">
        <color rgba="0.1 0.5 0 1"/>
      </material>
    </visual>
  </link>
<!--
  <link name="lwheel">
    <visual>
      <geometry>
        <cylinder length="0.008" radius="0.046"/>
      </geometry>
      <origin rpy="0 1.57075 0" xyz="0 0 0"/>
      <material name="cyan">
        <color rgba="0 0.5 0.5 1"/>
      </material>
    </visual>
  </link>
-->
  <link name="lwheel">
    <visual>
      <geometry>
        <cylinder length="0.008" radius="0.046"/>
      </geometry>
      <origin rpy="0 1.57075 0" xyz="0 0 0"/>
      <material name="purple">
        <color rgba="1 1 0 1"/>
      </material>
    </visual>
  </link>

  <joint name="base_to_lconnection" type="continuous">
    <parent link="base_link"/>
    <child link="lwheel"/>
    <origin xyz="0.03 0.084 0.046" rpy="0 0 1.57075"/>
  </joint>
<!--
  <joint name="base_to_lwheel" type="continuous">
    <parent link="lwheel_base_connection"/>
    <child link="lwheel"/>
    <origin xyz="0.008 0 0" rpy="0 0 0"/>
  </joint>
-->
<!--
  <link name="rwheel">
    <visual>
      <geometry>
        <cylinder length="0.008" radius="0.046"/>
      </geometry>
      <origin rpy="0 1.57075 0" xyz="0 0 0"/>
      <material name="cyan">
        <color rgba="0 0.5 0.5 1"/>
      </material>
    </visual>
  </link>
-->
  <link name="rwheel">
    <visual>
      <geometry>
        <cylinder length="0.008" radius="0.046"/>
      </geometry>
      <origin rpy="0 1.57075 0" xyz="0 0 0"/>
      <material name="purple">
        <color rgba="1 1 0 1"/>
      </material>
    </visual>
  </link>

  <joint name="base_to_rconnection" type="continuous">
    <parent link="base_link"/>
    <child link="rwheel"/>
    <origin xyz="0.03 -0.084 0.046" rpy="0 0 1.57075"/>
  </joint>

  <!-- link rpy 0 1.57075 0 -->
  <!-- joint rpy 0 0 1.57075 -->
<!--
  <joint name="base_to_rwheel" type="continuous">
    <parent link="rwheel_base_connection"/>
    <child link="rwheel"/>
    <origin xyz="-0.008 0 0" rpy="0 0 0"/>
  </joint>
-->

  <link name="fwheel_attach">
    <visual>
      <geometry>
        <cylinder length="0.016" radius="0.023"/>
      </geometry>
      <origin rpy="0 0 0" xyz="0 0 0"/>
      <material name="red">
        <color rgba="1 0 0 1"/>
      </material>
    </visual>
  </link>

  <joint name="base_to_fattach" type="fixed">
    <parent link="base_link"/>
    <child link="fwheel_attach"/>
    <origin xyz="-0.05 0 0.008" rpy="0 0 0"/>
  </joint>
  <!--
  <link name="fwheel">
    <visual>
      <geometry>
        <cylinder length="0.005" radius="0.010"/>
      </geometry>
      <origin rpy="1.578 0 0" xyz="-0.03 0 0"/>
      <material name="black">
        <color rgba="0 0 0 1"/>
      </material>
    </visual>
  </link>

  <joint name="base_to_fwheel" type="fixed">
    <parent link="base_link"/>
    <child link="fwheel"/>
    <origin xyz="0.13 0 0.02" rpy="0 0 0"/>
  </joint>
  -->

</robot>
